#VRML_SIM R2023a utf8

EXTERNPROTO "https://raw.githubusercontent.com/cyberbotics/webots/R2023a/projects/appearances/protos/Parquetry.proto"
EXTERNPROTO "https://raw.githubusercontent.com/cyberbotics/webots/R2023a/projects/objects/floors/protos/RectangleArena.proto"
EXTERNPROTO "https://raw.githubusercontent.com/cyberbotics/webots/R2023a/projects/objects/backgrounds/protos/TexturedBackground.proto"
EXTERNPROTO "https://raw.githubusercontent.com/cyberbotics/webots/R2023a/projects/objects/road/protos/Roundabout.proto"

WorldInfo {
  coordinateSystem "NUE"
}
Viewpoint {
  orientation 0.7071000384052415 -0.7070999591338322 0.0043798950031663725 3.1328333066005634
  position 0.12680561327371087 2.1542892850968625 0.051093620752244336
}
TexturedBackground {
  texture "noon_cloudy_countryside"
}
RectangleArena {
  translation 0 -5 0
  rotation -1 0 0 1.57079632679
  floorSize 10 10
  floorAppearance Parquetry {
    type "light strip"
    colorOverride 0.777 1 0.419
  }
}
Robot {
  translation -1.53337 -4.9 0.129006
  rotation 0 1 0 3.1408
  children [
    LightSensor {
      translation 0.03 0 0.1
      rotation 0 1 0 -1.57
      scale 3 3 3
      children [
        Shape {
          appearance PBRAppearance {
            baseColor 0 0 1
            roughness 1
            metalness 0
          }
          geometry Box {
            size 0.01 0.01 0.01
          }
        }
      ]
      name "ls_left"
    }
    LightSensor {
      translation -0.03 0 0.1
      rotation 0 1 0 -1.57
      scale 3 3 3
      children [
        Shape {
          appearance PBRAppearance {
            baseColor 0 0 1
            roughness 1
            metalness 0
          }
          geometry Box {
            size 0.01 0.01 0.01
          }
        }
      ]
      name "ls_right"
    }
    DEF BODY Shape {
      appearance PBRAppearance {
        baseColor 0.917647 0.145098 0.145098
        roughness 1
        metalness 0
      }
      geometry Box {
        size 0.1 0.05 0.2
      }
    }
    DEF WHEEL1 HingeJoint {
      jointParameters HingeJointParameters {
        position 647.1380516011527
        anchor 0.06 0 0.05
      }
      device [
        RotationalMotor {
          name "wheel1"
        }
      ]
      endPoint Solid {
        translation 0.06 0 0.05
        rotation 1 0 0 6.253150268834896
        children [
          DEF WHEEL Transform {
            rotation -0.5773488553723224 -0.5773509760969792 0.5773509760969793 2.094397223120449
            children [
              Shape {
                appearance PBRAppearance {
                  baseColor 0.305882 0.898039 0.25098
                  roughness 1
                  metalness 0
                }
                geometry Cylinder {
                  height 0.02
                  radius 0.04
                  subdivision 24
                }
              }
            ]
          }
        ]
        boundingObject USE WHEEL
        physics Physics {
        }
      }
    }
    DEF WHEEL2 HingeJoint {
      jointParameters HingeJointParameters {
        position 658.5660414304194
        anchor -0.06 0 0.05
      }
      device [
        RotationalMotor {
          name "wheel2"
        }
      ]
      endPoint Solid {
        translation -0.06 0 0.05
        rotation 1 0 0 5.114769483742438
        children [
          USE WHEEL
        ]
        name "solid(1)"
        boundingObject USE WHEEL
        physics Physics {
        }
      }
    }
    DEF WHEEL3 HingeJoint {
      jointParameters HingeJointParameters {
        position 647.1380548331853
        anchor 0.06 0 -0.05
      }
      device [
        RotationalMotor {
          name "wheel3"
        }
      ]
      endPoint Solid {
        translation 0.06 0 -0.05
        rotation 1 0 0 6.253153500867447
        children [
          USE WHEEL
        ]
        name "solid(2)"
        boundingObject USE WHEEL
        physics Physics {
        }
      }
    }
    DEF WHEEL4 HingeJoint {
      jointParameters HingeJointParameters {
        position 658.5660471062939
        anchor -0.06 0 -0.05
      }
      device [
        RotationalMotor {
          name "wheel4"
        }
      ]
      endPoint Solid {
        translation -0.06 0 -0.05
        rotation 1 0 0 5.114775159616928
        children [
          USE WHEEL
        ]
        name "solid(3)"
        boundingObject USE WHEEL
        physics Physics {
        }
      }
    }
  ]
  boundingObject USE BODY
  physics Physics {
    density -1
    mass 1
  }
  locked TRUE
  controller "task2b_clockwise"
}
Roundabout {
  translation 0 -4.99 0
  rotation -0.28108491207243697 0.6785987877241534 0.6785977877244662 2.59357
  borderWidth 0.5
  borderHeight 0
  innerRadius 1
  outerRadius 2
  centerTexture [
    ""
  ]
  centerTextureScale 0 0
  startRoadsWidth 1
}
